grep: warning: GREP_OPTIONS is deprecated; please use an alias or script
Warning: Unable to use numba in PP-Tracking, please install numba, for example(python3.7): `pip install numba==0.56.4`
Warning: Unable to use numba in PP-Tracking, please install numba, for example(python3.7): `pip install numba==0.56.4`
Warning: import ppdet from source directory without installing, run 'python setup.py install' to install ppdet firstly
I0314 18:05:52.433661 31404 gen_comm_id_helper.cc:205] Server listening on: 127.0.0.1:48731 successful.
I0314 18:05:55.388419 31404 nccl_context.cc:83] init nccl context nranks: 8 local rank: 6 gpu id: 6 ring id: 0
W0314 18:05:56.884729 31404 gpu_resources.cc:61] Please NOTE: device: 6, GPU Compute Capability: 6.1, Driver API Version: 10.2, Runtime API Version: 10.2
W0314 18:05:56.889333 31404 gpu_resources.cc:91] device: 6, cuDNN Version: 7.6.
loading annotations into memory...
Done (t=0.96s)
creating index...
index created!
loading annotations into memory...
Done (t=0.43s)
creating index...
index created!
Annotation file: dataset/coco/semi_annotations/instances_train2017.1@5-unlabeled.json does not contains ground truth and load image information only.
W0314 18:06:15.987242 31404 reducer.cc:694] All parameters are involved in the backward pass. It is recommended to set find_unused_parameters to False to improve performance. However, if unused parameters appear in subsequent iterative training, then an error will occur. Please make it clear that in the subsequent training, there will be no parameters that are not used in the backward pass, and then set find_unused_parameters


--------------------------------------
C++ Traceback (most recent call last):
--------------------------------------
0   paddle::imperative::BasicEngine::Execute()
1   paddle::imperative::OpBase::ClearBackwardTrace()
2   std::_Rb_tree<std::string, std::pair<std::string const, paddle::imperative::SavedVariableWrapperList>, std::_Select1st<std::pair<std::string const, paddle::imperative::SavedVariableWrapperList> >, std::less<std::string >, std::allocator<std::pair<std::string const, paddle::imperative::SavedVariableWrapperList> > >::_M_erase(std::_Rb_tree_node<std::pair<std::string const, paddle::imperative::SavedVariableWrapperList> >*)
3   std::_Sp_counted_ptr_inplace<paddle::imperative::VariableWrapper, std::allocator<paddle::imperative::VariableWrapper>, (__gnu_cxx::_Lock_policy)2>::_M_dispose()
4   std::_Sp_counted_base<(__gnu_cxx::_Lock_policy)2>::_M_release()
5   paddle::framework::Variable::PlaceholderImpl<phi::DenseTensor>::~PlaceholderImpl()
6   std::_Sp_counted_base<(__gnu_cxx::_Lock_policy)2>::_M_release()
7   std::_Sp_counted_deleter<phi::Allocation*, std::function<void (phi::Allocation*)>, std::allocator<void>, (__gnu_cxx::_Lock_policy)2>::_M_dispose()
8   paddle::memory::allocation::StatAllocator::FreeImpl(phi::Allocation*)
9   paddle::memory::allocation::RetryAllocator::FreeImpl(phi::Allocation*)
10  paddle::memory::allocation::StreamSafeCUDAAllocator::FreeImpl(phi::Allocation*)
11  paddle::memory::allocation::StreamSafeCUDAAllocation::~StreamSafeCUDAAllocation()
12  paddle::memory::allocation::AutoGrowthBestFitAllocator::FreeImpl(phi::Allocation*)
13  std::_Rb_tree<std::pair<unsigned long, void*>, std::pair<std::pair<unsigned long, void*> const, std::_List_iterator<paddle::memory::allocation::AutoGrowthBestFitAllocator::Block> >, std::_Select1st<std::pair<std::pair<unsigned long, void*> const, std::_List_iterator<paddle::memory::allocation::AutoGrowthBestFitAllocator::Block> > >, std::less<std::pair<unsigned long, void*> >, std::allocator<std::pair<std::pair<unsigned long, void*> const, std::_List_iterator<paddle::memory::allocation::AutoGrowthBestFitAllocator::Block> > > >::erase(std::pair<unsigned long, void*> const&)

----------------------
Error Message Summary:
----------------------
FatalError: `Termination signal` is detected by the operating system.
  [TimeInfo: *** Aborted at 1678817330 (unix time) try "date -d @1678817330" if you are using GNU date ***]
  [SignalInfo: *** SIGTERM (@0x7a55) received by PID 31404 (TID 0x7f9814cc0700) from PID 31317 ***]

grep: warning: GREP_OPTIONS is deprecated; please use an alias or script
Warning: Unable to use numba in PP-Tracking, please install numba, for example(python3.7): `pip install numba==0.56.4`
Warning: Unable to use numba in PP-Tracking, please install numba, for example(python3.7): `pip install numba==0.56.4`
Warning: import ppdet from source directory without installing, run 'python setup.py install' to install ppdet firstly
I0314 18:11:57.241163 15923 gen_comm_id_helper.cc:205] Server listening on: 127.0.0.1:36822 successful.
I0314 18:12:00.114893 15923 nccl_context.cc:83] init nccl context nranks: 8 local rank: 6 gpu id: 6 ring id: 0
W0314 18:12:01.617774 15923 gpu_resources.cc:61] Please NOTE: device: 6, GPU Compute Capability: 6.1, Driver API Version: 10.2, Runtime API Version: 10.2
W0314 18:12:01.622426 15923 gpu_resources.cc:91] device: 6, cuDNN Version: 7.6.
loading annotations into memory...
Done (t=0.97s)
creating index...
index created!
loading annotations into memory...
Done (t=0.42s)
creating index...
index created!
Annotation file: dataset/coco/semi_annotations/instances_train2017.1@5-unlabeled.json does not contains ground truth and load image information only.
W0314 18:12:20.666083 15923 reducer.cc:694] All parameters are involved in the backward pass. It is recommended to set find_unused_parameters to False to improve performance. However, if unused parameters appear in subsequent iterative training, then an error will occur. Please make it clear that in the subsequent training, there will be no parameters that are not used in the backward pass, and then set find_unused_parameters
grep: warning: GREP_OPTIONS is deprecated; please use an alias or script
Warning: Unable to use numba in PP-Tracking, please install numba, for example(python3.7): `pip install numba==0.56.4`
Warning: Unable to use numba in PP-Tracking, please install numba, for example(python3.7): `pip install numba==0.56.4`
Warning: import ppdet from source directory without installing, run 'python setup.py install' to install ppdet firstly
I0315 07:40:59.428172  5280 gen_comm_id_helper.cc:205] Server listening on: 127.0.0.1:16729 successful.
I0315 07:41:02.156715  5280 nccl_context.cc:83] init nccl context nranks: 8 local rank: 6 gpu id: 6 ring id: 0
W0315 07:41:03.795452  5280 gpu_resources.cc:61] Please NOTE: device: 6, GPU Compute Capability: 6.1, Driver API Version: 10.2, Runtime API Version: 10.2
W0315 07:41:03.800186  5280 gpu_resources.cc:91] device: 6, cuDNN Version: 7.6.
loading annotations into memory...
Done (t=0.97s)
creating index...
index created!
loading annotations into memory...
Done (t=0.42s)
creating index...
index created!
Annotation file: dataset/coco/semi_annotations/instances_train2017.1@5-unlabeled.json does not contains ground truth and load image information only.
W0315 07:41:22.388113  5280 reducer.cc:694] All parameters are involved in the backward pass. It is recommended to set find_unused_parameters to False to improve performance. However, if unused parameters appear in subsequent iterative training, then an error will occur. Please make it clear that in the subsequent training, there will be no parameters that are not used in the backward pass, and then set find_unused_parameters
fail to map sample transform [Decode_5c1d37] with error: [Errno 2] No such file or directory: 'dataset/coco/train2017/000000294159.jpg' and stack:
Traceback (most recent call last):
  File "/workspace/zhaokang/SSOD/PaddleDetection/ppdet/data/reader.py", line 455, in __iter__
    label_samples = next(self.label_loader_iter)
  File "/usr/local/python3.7.0/lib/python3.7/site-packages/paddle/fluid/dataloader/dataloader_iter.py", line 773, in __next__
    six.reraise(*sys.exc_info())
  File "/usr/local/python3.7.0/lib/python3.7/site-packages/six.py", line 719, in reraise
    raise value
  File "/usr/local/python3.7.0/lib/python3.7/site-packages/paddle/fluid/dataloader/dataloader_iter.py", line 746, in __next__
    data = self._reader.read_next_var_list()
StopIteration

During handling of the above exception, another exception occurred:

Traceback (most recent call last):
  File "/workspace/zhaokang/SSOD/PaddleDetection/ppdet/data/reader.py", line 347, in __call__
    data = f(data)
  File "/workspace/zhaokang/SSOD/PaddleDetection/ppdet/data/transform/operators.py", line 105, in __call__
    sample = self.apply(sample, context)
  File "/workspace/zhaokang/SSOD/PaddleDetection/ppdet/data/transform/operators.py", line 122, in apply
    with open(sample['im_file'], 'rb') as f:
FileNotFoundError: [Errno 2] No such file or directory: 'dataset/coco/train2017/000000294159.jpg'

fail to map sample transform [Decode_85ef15] with error: [Errno 2] No such file or directory: 'dataset/coco/train2017/000000115604.jpg' and stack:
Traceback (most recent call last):
  File "/workspace/zhaokang/SSOD/PaddleDetection/ppdet/data/reader.py", line 461, in __iter__
    unlabel_samples = next(self.unlabel_loader_iter)
  File "/usr/local/python3.7.0/lib/python3.7/site-packages/paddle/fluid/dataloader/dataloader_iter.py", line 773, in __next__
    six.reraise(*sys.exc_info())
  File "/usr/local/python3.7.0/lib/python3.7/site-packages/six.py", line 719, in reraise
    raise value
  File "/usr/local/python3.7.0/lib/python3.7/site-packages/paddle/fluid/dataloader/dataloader_iter.py", line 746, in __next__
    data = self._reader.read_next_var_list()
StopIteration

During handling of the above exception, another exception occurred:

Traceback (most recent call last):
  File "/workspace/zhaokang/SSOD/PaddleDetection/ppdet/data/reader.py", line 347, in __call__
    data = f(data)
  File "/workspace/zhaokang/SSOD/PaddleDetection/ppdet/data/transform/operators.py", line 105, in __call__
    sample = self.apply(sample, context)
  File "/workspace/zhaokang/SSOD/PaddleDetection/ppdet/data/transform/operators.py", line 122, in apply
    with open(sample['im_file'], 'rb') as f:
FileNotFoundError: [Errno 2] No such file or directory: 'dataset/coco/train2017/000000115604.jpg'

Exception in thread Thread-331:
Traceback (most recent call last):
  File "/usr/local/python3.7.0/lib/python3.7/threading.py", line 917, in _bootstrap_inner
    self.run()
  File "/usr/local/python3.7.0/lib/python3.7/threading.py", line 865, in run
    self._target(*self._args, **self._kwargs)
  File "/usr/local/python3.7.0/lib/python3.7/site-packages/paddle/fluid/dataloader/dataloader_iter.py", line 534, in _thread_loop
    batch = self._get_data()
  File "/usr/local/python3.7.0/lib/python3.7/site-packages/paddle/fluid/dataloader/dataloader_iter.py", line 671, in _get_data
    batch.reraise()
  File "/usr/local/python3.7.0/lib/python3.7/site-packages/paddle/fluid/dataloader/worker.py", line 169, in reraise
    raise self.exc_type(msg)
FileNotFoundError: DataLoader worker(1) caught FileNotFoundError with message:
Traceback (most recent call last):
  File "/workspace/zhaokang/SSOD/PaddleDetection/ppdet/data/reader.py", line 461, in __iter__
    unlabel_samples = next(self.unlabel_loader_iter)
  File "/usr/local/python3.7.0/lib/python3.7/site-packages/paddle/fluid/dataloader/dataloader_iter.py", line 773, in __next__
    six.reraise(*sys.exc_info())
  File "/usr/local/python3.7.0/lib/python3.7/site-packages/six.py", line 719, in reraise
    raise value
  File "/usr/local/python3.7.0/lib/python3.7/site-packages/paddle/fluid/dataloader/dataloader_iter.py", line 746, in __next__
    data = self._reader.read_next_var_list()
StopIteration

During handling of the above exception, another exception occurred:

Traceback (most recent call last):
  File "/usr/local/python3.7.0/lib/python3.7/site-packages/paddle/fluid/dataloader/worker.py", line 336, in _worker_loop
    batch = fetcher.fetch(indices)
  File "/usr/local/python3.7.0/lib/python3.7/site-packages/paddle/fluid/dataloader/fetcher.py", line 121, in fetch
    data.append(self.dataset[idx])
  File "/workspace/zhaokang/SSOD/PaddleDetection/ppdet/data/source/coco.py", line 587, in __getitem__
    return self.transform(roidb)
  File "/workspace/zhaokang/SSOD/PaddleDetection/ppdet/data/reader.py", line 353, in __call__
    raise e
  File "/workspace/zhaokang/SSOD/PaddleDetection/ppdet/data/reader.py", line 347, in __call__
    data = f(data)
  File "/workspace/zhaokang/SSOD/PaddleDetection/ppdet/data/transform/operators.py", line 105, in __call__
    sample = self.apply(sample, context)
  File "/workspace/zhaokang/SSOD/PaddleDetection/ppdet/data/transform/operators.py", line 122, in apply
    with open(sample['im_file'], 'rb') as f:
FileNotFoundError: [Errno 2] No such file or directory: 'dataset/coco/train2017/000000115604.jpg'


Exception in thread Thread-330:
Traceback (most recent call last):
  File "/usr/local/python3.7.0/lib/python3.7/threading.py", line 917, in _bootstrap_inner
    self.run()
  File "/usr/local/python3.7.0/lib/python3.7/threading.py", line 865, in run
    self._target(*self._args, **self._kwargs)
  File "/usr/local/python3.7.0/lib/python3.7/site-packages/paddle/fluid/dataloader/dataloader_iter.py", line 534, in _thread_loop
    batch = self._get_data()
  File "/usr/local/python3.7.0/lib/python3.7/site-packages/paddle/fluid/dataloader/dataloader_iter.py", line 671, in _get_data
    batch.reraise()
  File "/usr/local/python3.7.0/lib/python3.7/site-packages/paddle/fluid/dataloader/worker.py", line 169, in reraise
    raise self.exc_type(msg)
FileNotFoundError: DataLoader worker(1) caught FileNotFoundError with message:
Traceback (most recent call last):
  File "/workspace/zhaokang/SSOD/PaddleDetection/ppdet/data/reader.py", line 455, in __iter__
    label_samples = next(self.label_loader_iter)
  File "/usr/local/python3.7.0/lib/python3.7/site-packages/paddle/fluid/dataloader/dataloader_iter.py", line 773, in __next__
    six.reraise(*sys.exc_info())
  File "/usr/local/python3.7.0/lib/python3.7/site-packages/six.py", line 719, in reraise
    raise value
  File "/usr/local/python3.7.0/lib/python3.7/site-packages/paddle/fluid/dataloader/dataloader_iter.py", line 746, in __next__
    data = self._reader.read_next_var_list()
StopIteration

During handling of the above exception, another exception occurred:

Traceback (most recent call last):
  File "/usr/local/python3.7.0/lib/python3.7/site-packages/paddle/fluid/dataloader/worker.py", line 336, in _worker_loop
    batch = fetcher.fetch(indices)
  File "/usr/local/python3.7.0/lib/python3.7/site-packages/paddle/fluid/dataloader/fetcher.py", line 121, in fetch
    data.append(self.dataset[idx])
  File "/workspace/zhaokang/SSOD/PaddleDetection/ppdet/data/source/coco.py", line 587, in __getitem__
    return self.transform(roidb)
  File "/workspace/zhaokang/SSOD/PaddleDetection/ppdet/data/reader.py", line 353, in __call__
    raise e
  File "/workspace/zhaokang/SSOD/PaddleDetection/ppdet/data/reader.py", line 347, in __call__
    data = f(data)
  File "/workspace/zhaokang/SSOD/PaddleDetection/ppdet/data/transform/operators.py", line 105, in __call__
    sample = self.apply(sample, context)
  File "/workspace/zhaokang/SSOD/PaddleDetection/ppdet/data/transform/operators.py", line 122, in apply
    with open(sample['im_file'], 'rb') as f:
FileNotFoundError: [Errno 2] No such file or directory: 'dataset/coco/train2017/000000294159.jpg'


fail to map sample transform [Decode_5c1d37] with error: [Errno 2] No such file or directory: 'dataset/coco/train2017/000000043411.jpg' and stack:
Traceback (most recent call last):
  File "/workspace/zhaokang/SSOD/PaddleDetection/ppdet/data/reader.py", line 455, in __iter__
    label_samples = next(self.label_loader_iter)
  File "/usr/local/python3.7.0/lib/python3.7/site-packages/paddle/fluid/dataloader/dataloader_iter.py", line 773, in __next__
    six.reraise(*sys.exc_info())
  File "/usr/local/python3.7.0/lib/python3.7/site-packages/six.py", line 719, in reraise
    raise value
  File "/usr/local/python3.7.0/lib/python3.7/site-packages/paddle/fluid/dataloader/dataloader_iter.py", line 746, in __next__
    data = self._reader.read_next_var_list()
StopIteration

During handling of the above exception, another exception occurred:

Traceback (most recent call last):
  File "/workspace/zhaokang/SSOD/PaddleDetection/ppdet/data/reader.py", line 347, in __call__
    data = f(data)
  File "/workspace/zhaokang/SSOD/PaddleDetection/ppdet/data/transform/operators.py", line 105, in __call__
    sample = self.apply(sample, context)
  File "/workspace/zhaokang/SSOD/PaddleDetection/ppdet/data/transform/operators.py", line 122, in apply
    with open(sample['im_file'], 'rb') as f:
FileNotFoundError: [Errno 2] No such file or directory: 'dataset/coco/train2017/000000043411.jpg'

fail to map sample transform [Decode_85ef15] with error: [Errno 2] No such file or directory: 'dataset/coco/train2017/000000565670.jpg' and stack:
Traceback (most recent call last):
  File "/workspace/zhaokang/SSOD/PaddleDetection/ppdet/data/reader.py", line 461, in __iter__
    unlabel_samples = next(self.unlabel_loader_iter)
  File "/usr/local/python3.7.0/lib/python3.7/site-packages/paddle/fluid/dataloader/dataloader_iter.py", line 773, in __next__
    six.reraise(*sys.exc_info())
  File "/usr/local/python3.7.0/lib/python3.7/site-packages/six.py", line 719, in reraise
    raise value
  File "/usr/local/python3.7.0/lib/python3.7/site-packages/paddle/fluid/dataloader/dataloader_iter.py", line 746, in __next__
    data = self._reader.read_next_var_list()
StopIteration

During handling of the above exception, another exception occurred:

Traceback (most recent call last):
  File "/workspace/zhaokang/SSOD/PaddleDetection/ppdet/data/reader.py", line 347, in __call__
    data = f(data)
  File "/workspace/zhaokang/SSOD/PaddleDetection/ppdet/data/transform/operators.py", line 105, in __call__
    sample = self.apply(sample, context)
  File "/workspace/zhaokang/SSOD/PaddleDetection/ppdet/data/transform/operators.py", line 122, in apply
    with open(sample['im_file'], 'rb') as f:
FileNotFoundError: [Errno 2] No such file or directory: 'dataset/coco/train2017/000000565670.jpg'

fail to map sample transform [Decode_5c1d37] with error: [Errno 2] No such file or directory: 'dataset/coco/train2017/000000413625.jpg' and stack:
Traceback (most recent call last):
  File "/workspace/zhaokang/SSOD/PaddleDetection/ppdet/data/reader.py", line 455, in __iter__
    unlabel_samples = next(self.unlabel_loader_iter)
  File "/usr/local/python3.7.0/lib/python3.7/site-packages/paddle/fluid/dataloader/dataloader_iter.py", line 773, in __next__
    six.reraise(*sys.exc_info())
  File "/usr/local/python3.7.0/lib/python3.7/site-packages/six.py", line 719, in reraise
    raise value
  File "/usr/local/python3.7.0/lib/python3.7/site-packages/paddle/fluid/dataloader/dataloader_iter.py", line 746, in __next__
    data = self._reader.read_next_var_list()
StopIteration

During handling of the above exception, another exception occurred:

Traceback (most recent call last):
  File "/workspace/zhaokang/SSOD/PaddleDetection/ppdet/data/reader.py", line 347, in __call__
    except Exception as e:
  File "/workspace/zhaokang/SSOD/PaddleDetection/ppdet/data/transform/operators.py", line 105, in __call__
    sample = self.apply(sample, context)
  File "/workspace/zhaokang/SSOD/PaddleDetection/ppdet/data/transform/operators.py", line 122, in apply
    with open(sample['im_file'], 'rb') as f:
FileNotFoundError: [Errno 2] No such file or directory: 'dataset/coco/train2017/000000413625.jpg'

fail to map sample transform [Decode_85ef15] with error: [Errno 2] No such file or directory: 'dataset/coco/train2017/000000019167.jpg' and stack:
Traceback (most recent call last):
  File "/workspace/zhaokang/SSOD/PaddleDetection/ppdet/data/reader.py", line 461, in __iter__
    label_samples[0],  # sup weak
  File "/usr/local/python3.7.0/lib/python3.7/site-packages/paddle/fluid/dataloader/dataloader_iter.py", line 773, in __next__
    six.reraise(*sys.exc_info())
  File "/usr/local/python3.7.0/lib/python3.7/site-packages/six.py", line 719, in reraise
    raise value
  File "/usr/local/python3.7.0/lib/python3.7/site-packages/paddle/fluid/dataloader/dataloader_iter.py", line 746, in __next__
    data = self._reader.read_next_var_list()
StopIteration

During handling of the above exception, another exception occurred:

Traceback (most recent call last):
  File "/workspace/zhaokang/SSOD/PaddleDetection/ppdet/data/reader.py", line 347, in __call__
    except Exception as e:
  File "/workspace/zhaokang/SSOD/PaddleDetection/ppdet/data/transform/operators.py", line 105, in __call__
    sample = self.apply(sample, context)
  File "/workspace/zhaokang/SSOD/PaddleDetection/ppdet/data/transform/operators.py", line 122, in apply
    with open(sample['im_file'], 'rb') as f:
FileNotFoundError: [Errno 2] No such file or directory: 'dataset/coco/train2017/000000019167.jpg'

fail to map sample transform [Decode_5c1d37] with error: [Errno 2] No such file or directory: 'dataset/coco/train2017/000000460168.jpg' and stack:
Traceback (most recent call last):
  File "/workspace/zhaokang/SSOD/PaddleDetection/ppdet/data/reader.py", line 455, in __iter__
    unlabel_samples = next(self.unlabel_loader_iter)
  File "/usr/local/python3.7.0/lib/python3.7/site-packages/paddle/fluid/dataloader/dataloader_iter.py", line 746, in __next__
    data = self._reader.read_next_var_list()
SystemError: (Fatal) Blocking queue is killed because the data reader raises an exception.
  [Hint: Expected killed_ != true, but received killed_:1 == true:1.] (at /paddle/paddle/fluid/operators/reader/blocking_queue.h:166)


During handling of the above exception, another exception occurred:

Traceback (most recent call last):
  File "/workspace/zhaokang/SSOD/PaddleDetection/ppdet/data/reader.py", line 347, in __call__
    except Exception as e:
  File "/workspace/zhaokang/SSOD/PaddleDetection/ppdet/data/transform/operators.py", line 105, in __call__
    sample = self.apply(sample, context)
  File "/workspace/zhaokang/SSOD/PaddleDetection/ppdet/data/transform/operators.py", line 122, in apply
    with open(sample['im_file'], 'rb') as f:
FileNotFoundError: [Errno 2] No such file or directory: 'dataset/coco/train2017/000000460168.jpg'

fail to map sample transform [Decode_5c1d37] with error: [Errno 2] No such file or directory: 'dataset/coco/train2017/000000092093.jpg' and stack:
Traceback (most recent call last):
  File "/workspace/zhaokang/SSOD/PaddleDetection/ppdet/data/reader.py", line 455, in __iter__
    unlabel_samples = next(self.unlabel_loader_iter)
  File "/usr/local/python3.7.0/lib/python3.7/site-packages/paddle/fluid/dataloader/dataloader_iter.py", line 746, in __next__
    data = self._reader.read_next_var_list()
SystemError: (Fatal) Blocking queue is killed because the data reader raises an exception.
  [Hint: Expected killed_ != true, but received killed_:1 == true:1.] (at /paddle/paddle/fluid/operators/reader/blocking_queue.h:166)


During handling of the above exception, another exception occurred:

Traceback (most recent call last):
  File "/workspace/zhaokang/SSOD/PaddleDetection/ppdet/data/reader.py", line 347, in __call__
    except Exception as e:
  File "/workspace/zhaokang/SSOD/PaddleDetection/ppdet/data/transform/operators.py", line 105, in __call__
    sample = self.apply(sample, context)
  File "/workspace/zhaokang/SSOD/PaddleDetection/ppdet/data/transform/operators.py", line 122, in apply
    with open(sample['im_file'], 'rb') as f:
FileNotFoundError: [Errno 2] No such file or directory: 'dataset/coco/train2017/000000092093.jpg'

fail to map sample transform [Decode_5c1d37] with error: [Errno 2] No such file or directory: 'dataset/coco/train2017/000000235031.jpg' and stack:
Traceback (most recent call last):
  File "/workspace/zhaokang/SSOD/PaddleDetection/ppdet/data/reader.py", line 455, in __iter__
    unlabel_samples = next(self.unlabel_loader_iter)
  File "/usr/local/python3.7.0/lib/python3.7/site-packages/paddle/fluid/dataloader/dataloader_iter.py", line 746, in __next__
    data = self._reader.read_next_var_list()
SystemError: (Fatal) Blocking queue is killed because the data reader raises an exception.
  [Hint: Expected killed_ != true, but received killed_:1 == true:1.] (at /paddle/paddle/fluid/operators/reader/blocking_queue.h:166)


During handling of the above exception, another exception occurred:

Traceback (most recent call last):
  File "/workspace/zhaokang/SSOD/PaddleDetection/ppdet/data/reader.py", line 347, in __call__
    except Exception as e:
  File "/workspace/zhaokang/SSOD/PaddleDetection/ppdet/data/transform/operators.py", line 105, in __call__
    sample = self.apply(sample, context)
  File "/workspace/zhaokang/SSOD/PaddleDetection/ppdet/data/transform/operators.py", line 122, in apply
    with open(sample['im_file'], 'rb') as f:
FileNotFoundError: [Errno 2] No such file or directory: 'dataset/coco/train2017/000000235031.jpg'
fail to map sample transform [Decode_5c1d37] with error: [Errno 2] No such file or directory: 'dataset/coco/train2017/000000278335.jpg' and stack:
Traceback (most recent call last):
  File "/workspace/zhaokang/SSOD/PaddleDetection/ppdet/data/reader.py", line 455, in __iter__
    unlabel_samples = next(self.unlabel_loader_iter)
  File "/usr/local/python3.7.0/lib/python3.7/site-packages/paddle/fluid/dataloader/dataloader_iter.py", line 746, in __next__
    data = self._reader.read_next_var_list()
SystemError: (Fatal) Blocking queue is killed because the data reader raises an exception.
  [Hint: Expected killed_ != true, but received killed_:1 == true:1.] (at /paddle/paddle/fluid/operators/reader/blocking_queue.h:166)


During handling of the above exception, another exception occurred:

Traceback (most recent call last):
  File "/workspace/zhaokang/SSOD/PaddleDetection/ppdet/data/reader.py", line 347, in __call__
    except Exception as e:
  File "/workspace/zhaokang/SSOD/PaddleDetection/ppdet/data/transform/operators.py", line 105, in __call__
    sample = self.apply(sample, context)
  File "/workspace/zhaokang/SSOD/PaddleDetection/ppdet/data/transform/operators.py", line 122, in apply
    with open(sample['im_file'], 'rb') as f:
FileNotFoundError: [Errno 2] No such file or directory: 'dataset/coco/train2017/000000278335.jpg'


Exception in thread Thread-332:
Traceback (most recent call last):
  File "/usr/local/python3.7.0/lib/python3.7/threading.py", line 917, in _bootstrap_inner
    self.run()
  File "/usr/local/python3.7.0/lib/python3.7/threading.py", line 865, in run
    self._target(*self._args, **self._kwargs)
  File "/usr/local/python3.7.0/lib/python3.7/site-packages/paddle/fluid/dataloader/dataloader_iter.py", line 534, in _thread_loop
    batch = self._get_data()
  File "/usr/local/python3.7.0/lib/python3.7/site-packages/paddle/fluid/dataloader/dataloader_iter.py", line 671, in _get_data
    batch.reraise()
  File "/usr/local/python3.7.0/lib/python3.7/site-packages/paddle/fluid/dataloader/worker.py", line 169, in reraise
    raise self.exc_type(msg)
FileNotFoundError: DataLoader worker(0) caught FileNotFoundError with message:
Traceback (most recent call last):
  File "/workspace/zhaokang/SSOD/PaddleDetection/ppdet/data/reader.py", line 455, in __iter__
    unlabel_samples = next(self.unlabel_loader_iter)
  File "/usr/local/python3.7.0/lib/python3.7/site-packages/paddle/fluid/dataloader/dataloader_iter.py", line 746, in __next__
    data = self._reader.read_next_var_list()
SystemError: (Fatal) Blocking queue is killed because the data reader raises an exception.
  [Hint: Expected killed_ != true, but received killed_:1 == true:1.] (at /paddle/paddle/fluid/operators/reader/blocking_queue.h:166)


During handling of the above exception, another exception occurred:

Traceback (most recent call last):
  File "/usr/local/python3.7.0/lib/python3.7/site-packages/paddle/fluid/dataloader/worker.py", line 336, in _worker_loop
    batch = fetcher.fetch(indices)
  File "/usr/local/python3.7.0/lib/python3.7/site-packages/paddle/fluid/dataloader/fetcher.py", line 121, in fetch
    data.append(self.dataset[idx])
  File "/workspace/zhaokang/SSOD/PaddleDetection/ppdet/data/source/coco.py", line 587, in __getitem__
    return self.transform(roidb)
  File "/workspace/zhaokang/SSOD/PaddleDetection/ppdet/data/reader.py", line 353, in __call__
  File "/workspace/zhaokang/SSOD/PaddleDetection/ppdet/data/reader.py", line 347, in __call__
    except Exception as e:
  File "/workspace/zhaokang/SSOD/PaddleDetection/ppdet/data/transform/operators.py", line 105, in __call__
    sample = self.apply(sample, context)
  File "/workspace/zhaokang/SSOD/PaddleDetection/ppdet/data/transform/operators.py", line 122, in apply
    with open(sample['im_file'], 'rb') as f:
FileNotFoundError: [Errno 2] No such file or directory: 'dataset/coco/train2017/000000460168.jpg'


Traceback (most recent call last):
  File "/workspace/zhaokang/SSOD/PaddleDetection/ppdet/data/reader.py", line 455, in __iter__
fail to map sample transform [Decode_5c1d37] with error: [Errno 2] No such file or directory: 'dataset/coco/train2017/000000144242.jpg' and stack:
Traceback (most recent call last):
  File "/workspace/zhaokang/SSOD/PaddleDetection/ppdet/data/reader.py", line 455, in __iter__
    unlabel_samples = next(self.unlabel_loader_iter)
  File "/usr/local/python3.7.0/lib/python3.7/site-packages/paddle/fluid/dataloader/dataloader_iter.py", line 746, in __next__
    data = self._reader.read_next_var_list()
SystemError: (Fatal) Blocking queue is killed because the data reader raises an exception.
  [Hint: Expected killed_ != true, but received killed_:1 == true:1.] (at /paddle/paddle/fluid/operators/reader/blocking_queue.h:166)


During handling of the above exception, another exception occurred:

Traceback (most recent call last):
  File "/workspace/zhaokang/SSOD/PaddleDetection/ppdet/data/reader.py", line 347, in __call__
    except Exception as e:
  File "/workspace/zhaokang/SSOD/PaddleDetection/ppdet/data/transform/operators.py", line 105, in __call__
    sample = self.apply(sample, context)
  File "/workspace/zhaokang/SSOD/PaddleDetection/ppdet/data/transform/operators.py", line 122, in apply
    with open(sample['im_file'], 'rb') as f:
FileNotFoundError: [Errno 2] No such file or directory: 'dataset/coco/train2017/000000144242.jpg'

fail to map sample transform [Decode_5c1d37] with error: [Errno 2] No such file or directory: 'dataset/coco/train2017/000000232344.jpg' and stack:
Traceback (most recent call last):
  File "/workspace/zhaokang/SSOD/PaddleDetection/ppdet/data/reader.py", line 455, in __iter__
    unlabel_samples = next(self.unlabel_loader_iter)
  File "/usr/local/python3.7.0/lib/python3.7/site-packages/paddle/fluid/dataloader/dataloader_iter.py", line 746, in __next__
    data = self._reader.read_next_var_list()
SystemError: (Fatal) Blocking queue is killed because the data reader raises an exception.
  [Hint: Expected killed_ != true, but received killed_:1 == true:1.] (at /paddle/paddle/fluid/operators/reader/blocking_queue.h:166)


During handling of the above exception, another exception occurred:

Traceback (most recent call last):
  File "/workspace/zhaokang/SSOD/PaddleDetection/ppdet/data/reader.py", line 347, in __call__
    except Exception as e:
  File "/workspace/zhaokang/SSOD/PaddleDetection/ppdet/data/transform/operators.py", line 105, in __call__
    sample = self.apply(sample, context)
  File "/workspace/zhaokang/SSOD/PaddleDetection/ppdet/data/transform/operators.py", line 122, in apply
    with open(sample['im_file'], 'rb') as f:
FileNotFoundError: [Errno 2] No such file or directory: 'dataset/coco/train2017/000000232344.jpg'

fail to map sample transform [Decode_5c1d37] with error: [Errno 2] No such file or directory: 'dataset/coco/train2017/000000529871.jpg' and stack:
Traceback (most recent call last):
  File "/workspace/zhaokang/SSOD/PaddleDetection/ppdet/data/reader.py", line 455, in __iter__
    unlabel_samples = next(self.unlabel_loader_iter)
  File "/usr/local/python3.7.0/lib/python3.7/site-packages/paddle/fluid/dataloader/dataloader_iter.py", line 746, in __next__
    data = self._reader.read_next_var_list()
SystemError: (Fatal) Blocking queue is killed because the data reader raises an exception.
  [Hint: Expected killed_ != true, but received killed_:1 == true:1.] (at /paddle/paddle/fluid/operators/reader/blocking_queue.h:166)


During handling of the above exception, another exception occurred:

Traceback (most recent call last):
  File "/workspace/zhaokang/SSOD/PaddleDetection/ppdet/data/reader.py", line 347, in __call__
    except Exception as e:
  File "/workspace/zhaokang/SSOD/PaddleDetection/ppdet/data/transform/operators.py", line 105, in __call__
    sample = self.apply(sample, context)
  File "/workspace/zhaokang/SSOD/PaddleDetection/ppdet/data/transform/operators.py", line 122, in apply
    with open(sample['im_file'], 'rb') as f:
FileNotFoundError: [Errno 2] No such file or directory: 'dataset/coco/train2017/000000529871.jpg'

fail to map sample transform [Decode_5c1d37] with error: [Errno 2] No such file or directory: 'dataset/coco/train2017/000000482295.jpg' and stack:
Traceback (most recent call last):
  File "/workspace/zhaokang/SSOD/PaddleDetection/ppdet/data/reader.py", line 455, in __iter__
    unlabel_samples = next(self.unlabel_loader_iter)
  File "/usr/local/python3.7.0/lib/python3.7/site-packages/paddle/fluid/dataloader/dataloader_iter.py", line 746, in __next__
    data = self._reader.read_next_var_list()
SystemError: (Fatal) Blocking queue is killed because the data reader raises an exception.
  [Hint: Expected killed_ != true, but received killed_:1 == true:1.] (at /paddle/paddle/fluid/operators/reader/blocking_queue.h:166)


During handling of the above exception, another exception occurred:

Traceback (most recent call last):
  File "/workspace/zhaokang/SSOD/PaddleDetection/ppdet/data/reader.py", line 347, in __call__
    except Exception as e:
  File "/workspace/zhaokang/SSOD/PaddleDetection/ppdet/data/transform/operators.py", line 105, in __call__
    sample = self.apply(sample, context)
  File "/workspace/zhaokang/SSOD/PaddleDetection/ppdet/data/transform/operators.py", line 122, in apply
    with open(sample['im_file'], 'rb') as f:
FileNotFoundError: [Errno 2] No such file or directory: 'dataset/coco/train2017/000000482295.jpg'

    unlabel_samples = next(self.unlabel_loader_iter)
  File "/usr/local/python3.7.0/lib/python3.7/site-packages/paddle/fluid/dataloader/dataloader_iter.py", line 746, in __next__
    data = self._reader.read_next_var_list()
SystemError: (Fatal) Blocking queue is killed because the data reader raises an exception.
  [Hint: Expected killed_ != true, but received killed_:1 == true:1.] (at /paddle/paddle/fluid/operators/reader/blocking_queue.h:166)


During handling of the above exception, another exception occurred:

Traceback (most recent call last):
  File "tools/train.py", line 205, in <module>
  File "tools/train.py", line 201, in main
    if __name__ == "__main__":
  File "tools/train.py", line 154, in run
    def main():
  File "/workspace/zhaokang/SSOD/PaddleDetection/ppdet/engine/trainer_ssod.py", line 247, in train
    
  File "/workspace/zhaokang/SSOD/PaddleDetection/ppdet/data/reader.py", line 590, in __next__
    
  File "/workspace/zhaokang/SSOD/PaddleDetection/ppdet/data/reader.py", line 458, in __iter__
    unlabel_samples = next(self.unlabel_loader_iter)
  File "/usr/local/python3.7.0/lib/python3.7/site-packages/paddle/fluid/dataloader/dataloader_iter.py", line 746, in __next__
    data = self._reader.read_next_var_list()
SystemError: (Fatal) Blocking queue is killed because the data reader raises an exception.
  [Hint: Expected killed_ != true, but received killed_:1 == true:1.] (at /paddle/paddle/fluid/operators/reader/blocking_queue.h:166)

grep: warning: GREP_OPTIONS is deprecated; please use an alias or script
Warning: Unable to use numba in PP-Tracking, please install numba, for example(python3.7): `pip install numba==0.56.4`
Warning: Unable to use numba in PP-Tracking, please install numba, for example(python3.7): `pip install numba==0.56.4`
Warning: import ppdet from source directory without installing, run 'python setup.py install' to install ppdet firstly
I0319 13:08:36.686815  7468 gen_comm_id_helper.cc:205] Server listening on: 127.0.0.1:45175 successful.
I0319 13:08:39.692538  7468 nccl_context.cc:83] init nccl context nranks: 8 local rank: 6 gpu id: 6 ring id: 0
W0319 13:08:41.258083  7468 gpu_resources.cc:61] Please NOTE: device: 6, GPU Compute Capability: 6.1, Driver API Version: 10.2, Runtime API Version: 10.2
W0319 13:08:41.262879  7468 gpu_resources.cc:91] device: 6, cuDNN Version: 7.6.
Config dataset_dir dataset/coco is not exits, dataset config is not valid
Dataset /workspace/dataset/coco is not valid for reason above, try searching /root/.cache/paddle/dataset or downloading dataset...


--------------------------------------
C++ Traceback (most recent call last):
--------------------------------------
No stack trace in paddle, may be caused by external reasons.

----------------------
Error Message Summary:
----------------------
FatalError: `Termination signal` is detected by the operating system.
  [TimeInfo: *** Aborted at 1679231441 (unix time) try "date -d @1679231441" if you are using GNU date ***]
  [SignalInfo: *** SIGTERM (@0x1cd8) received by PID 7468 (TID 0x7f98b084b700) from PID 7384 ***]

grep: warning: GREP_OPTIONS is deprecated; please use an alias or script
grep: warning: GREP_OPTIONS is deprecated; please use an alias or script
Warning: Unable to use numba in PP-Tracking, please install numba, for example(python3.7): `pip install numba==0.56.4`
Warning: Unable to use numba in PP-Tracking, please install numba, for example(python3.7): `pip install numba==0.56.4`
Warning: import ppdet from source directory without installing, run 'python setup.py install' to install ppdet firstly
I0319 13:12:46.353447  8419 gen_comm_id_helper.cc:205] Server listening on: 127.0.0.1:15060 successful.
I0319 13:12:49.300458  8419 nccl_context.cc:83] init nccl context nranks: 8 local rank: 6 gpu id: 6 ring id: 0
W0319 13:12:50.849917  8419 gpu_resources.cc:61] Please NOTE: device: 6, GPU Compute Capability: 6.1, Driver API Version: 10.2, Runtime API Version: 10.2
W0319 13:12:50.854584  8419 gpu_resources.cc:91] device: 6, cuDNN Version: 7.6.
loading annotations into memory...
Done (t=2.08s)
creating index...
index created!
loading annotations into memory...
Done (t=0.53s)
creating index...
index created!
Annotation file: dataset/coco/semi_annotations/instances_train2017.1@10-unlabeled.json does not contains ground truth and load image information only.
W0319 13:13:12.023272  8419 reducer.cc:694] All parameters are involved in the backward pass. It is recommended to set find_unused_parameters to False to improve performance. However, if unused parameters appear in subsequent iterative training, then an error will occur. Please make it clear that in the subsequent training, there will be no parameters that are not used in the backward pass, and then set find_unused_parameters


--------------------------------------
C++ Traceback (most recent call last):
--------------------------------------
No stack trace in paddle, may be caused by external reasons.

----------------------
Error Message Summary:
----------------------
FatalError: `Termination signal` is detected by the operating system.
  [TimeInfo: *** Aborted at 1679231639 (unix time) try "date -d @1679231639" if you are using GNU date ***]
  [SignalInfo: *** SIGTERM (@0x208f) received by PID 8419 (TID 0x7f40f470d700) from PID 8335 ***]

