grep: warning: GREP_OPTIONS is deprecated; please use an alias or script
Warning: Unable to use numba in PP-Tracking, please install numba, for example(python3.7): `pip install numba==0.56.4`
Warning: Unable to use numba in PP-Tracking, please install numba, for example(python3.7): `pip install numba==0.56.4`
Warning: import ppdet from source directory without installing, run 'python setup.py install' to install ppdet firstly
I0314 18:05:52.434098 31409 gen_comm_id_helper.cc:205] Server listening on: 127.0.0.1:53980 successful.
I0314 18:05:55.388427 31409 nccl_context.cc:83] init nccl context nranks: 8 local rank: 7 gpu id: 7 ring id: 0
W0314 18:05:56.880873 31409 gpu_resources.cc:61] Please NOTE: device: 7, GPU Compute Capability: 6.1, Driver API Version: 10.2, Runtime API Version: 10.2
W0314 18:05:56.886004 31409 gpu_resources.cc:91] device: 7, cuDNN Version: 7.6.
loading annotations into memory...
Done (t=0.96s)
creating index...
index created!
loading annotations into memory...
Done (t=0.42s)
creating index...
index created!
Annotation file: dataset/coco/semi_annotations/instances_train2017.1@5-unlabeled.json does not contains ground truth and load image information only.
W0314 18:06:15.972138 31409 reducer.cc:694] All parameters are involved in the backward pass. It is recommended to set find_unused_parameters to False to improve performance. However, if unused parameters appear in subsequent iterative training, then an error will occur. Please make it clear that in the subsequent training, there will be no parameters that are not used in the backward pass, and then set find_unused_parameters


--------------------------------------
C++ Traceback (most recent call last):
--------------------------------------
0   paddle::imperative::BasicEngine::Execute()
1   paddle::imperative::PreparedOp::Run(paddle::imperative::NameVariableWrapperMap const&, paddle::imperative::NameVariableWrapperMap const&, paddle::framework::AttributeMap const&, paddle::framework::AttributeMap const&)
2   phi::KernelImpl<void (*)(phi::GPUContext const&, phi::DenseTensor const&, phi::DenseTensor const&, phi::DenseTensor const&, std::vector<int, std::allocator<int> > const&, std::vector<int, std::allocator<int> > const&, std::string const&, int, std::vector<int, std::allocator<int> > const&, std::string const&, bool, int, bool, phi::DenseTensor*, phi::DenseTensor*), &(void phi::ConvCudnnGradKernel<float, phi::GPUContext>(phi::GPUContext const&, phi::DenseTensor const&, phi::DenseTensor const&, phi::DenseTensor const&, std::vector<int, std::allocator<int> > const&, std::vector<int, std::allocator<int> > const&, std::string const&, int, std::vector<int, std::allocator<int> > const&, std::string const&, bool, int, bool, phi::DenseTensor*, phi::DenseTensor*))>::Compute(phi::KernelContext*)
3   void phi::ConvCudnnGradKernel<float, phi::GPUContext>(phi::GPUContext const&, phi::DenseTensor const&, phi::DenseTensor const&, phi::DenseTensor const&, std::vector<int, std::allocator<int> > const&, std::vector<int, std::allocator<int> > const&, std::string const&, int, std::vector<int, std::allocator<int> > const&, std::string const&, bool, int, bool, phi::DenseTensor*, phi::DenseTensor*)
4   paddle::operators::ConvArgsBase<cudnnContext*, cudnnDataType_t>::~ConvArgsBase()
5   cudnnDestroyConvolutionDescriptor

----------------------
Error Message Summary:
----------------------
FatalError: `Termination signal` is detected by the operating system.
  [TimeInfo: *** Aborted at 1678817330 (unix time) try "date -d @1678817330" if you are using GNU date ***]
  [SignalInfo: *** SIGTERM (@0x7a55) received by PID 31409 (TID 0x7fca8524b700) from PID 31317 ***]

grep: warning: GREP_OPTIONS is deprecated; please use an alias or script
Warning: Unable to use numba in PP-Tracking, please install numba, for example(python3.7): `pip install numba==0.56.4`
Warning: Unable to use numba in PP-Tracking, please install numba, for example(python3.7): `pip install numba==0.56.4`
Warning: import ppdet from source directory without installing, run 'python setup.py install' to install ppdet firstly
I0314 18:11:57.228888 15928 gen_comm_id_helper.cc:205] Server listening on: 127.0.0.1:10493 successful.
I0314 18:12:00.114907 15928 nccl_context.cc:83] init nccl context nranks: 8 local rank: 7 gpu id: 7 ring id: 0
W0314 18:12:01.612552 15928 gpu_resources.cc:61] Please NOTE: device: 7, GPU Compute Capability: 6.1, Driver API Version: 10.2, Runtime API Version: 10.2
W0314 18:12:01.617635 15928 gpu_resources.cc:91] device: 7, cuDNN Version: 7.6.
loading annotations into memory...
Done (t=0.97s)
creating index...
index created!
loading annotations into memory...
Done (t=0.43s)
creating index...
index created!
Annotation file: dataset/coco/semi_annotations/instances_train2017.1@5-unlabeled.json does not contains ground truth and load image information only.
W0314 18:12:20.682626 15928 reducer.cc:694] All parameters are involved in the backward pass. It is recommended to set find_unused_parameters to False to improve performance. However, if unused parameters appear in subsequent iterative training, then an error will occur. Please make it clear that in the subsequent training, there will be no parameters that are not used in the backward pass, and then set find_unused_parameters
grep: warning: GREP_OPTIONS is deprecated; please use an alias or script
Warning: Unable to use numba in PP-Tracking, please install numba, for example(python3.7): `pip install numba==0.56.4`
Warning: Unable to use numba in PP-Tracking, please install numba, for example(python3.7): `pip install numba==0.56.4`
Warning: import ppdet from source directory without installing, run 'python setup.py install' to install ppdet firstly
I0315 07:40:59.427886  5285 gen_comm_id_helper.cc:205] Server listening on: 127.0.0.1:47068 successful.
I0315 07:41:02.156751  5285 nccl_context.cc:83] init nccl context nranks: 8 local rank: 7 gpu id: 7 ring id: 0
W0315 07:41:03.788669  5285 gpu_resources.cc:61] Please NOTE: device: 7, GPU Compute Capability: 6.1, Driver API Version: 10.2, Runtime API Version: 10.2
W0315 07:41:03.794154  5285 gpu_resources.cc:91] device: 7, cuDNN Version: 7.6.
loading annotations into memory...
Done (t=0.96s)
creating index...
index created!
loading annotations into memory...
Done (t=0.42s)
creating index...
index created!
Annotation file: dataset/coco/semi_annotations/instances_train2017.1@5-unlabeled.json does not contains ground truth and load image information only.
W0315 07:41:22.390334  5285 reducer.cc:694] All parameters are involved in the backward pass. It is recommended to set find_unused_parameters to False to improve performance. However, if unused parameters appear in subsequent iterative training, then an error will occur. Please make it clear that in the subsequent training, there will be no parameters that are not used in the backward pass, and then set find_unused_parameters
fail to map sample transform [Decode_788c3c] with error: [Errno 2] No such file or directory: 'dataset/coco/train2017/000000303703.jpg' and stack:
Traceback (most recent call last):
  File "/workspace/zhaokang/SSOD/PaddleDetection/ppdet/data/reader.py", line 455, in __iter__
    label_samples = next(self.label_loader_iter)
  File "/usr/local/python3.7.0/lib/python3.7/site-packages/paddle/fluid/dataloader/dataloader_iter.py", line 773, in __next__
    six.reraise(*sys.exc_info())
  File "/usr/local/python3.7.0/lib/python3.7/site-packages/six.py", line 719, in reraise
    raise value
  File "/usr/local/python3.7.0/lib/python3.7/site-packages/paddle/fluid/dataloader/dataloader_iter.py", line 746, in __next__
    data = self._reader.read_next_var_list()
StopIteration

During handling of the above exception, another exception occurred:

Traceback (most recent call last):
  File "/workspace/zhaokang/SSOD/PaddleDetection/ppdet/data/reader.py", line 347, in __call__
    data = f(data)
  File "/workspace/zhaokang/SSOD/PaddleDetection/ppdet/data/transform/operators.py", line 105, in __call__
    sample = self.apply(sample, context)
  File "/workspace/zhaokang/SSOD/PaddleDetection/ppdet/data/transform/operators.py", line 122, in apply
    with open(sample['im_file'], 'rb') as f:
FileNotFoundError: [Errno 2] No such file or directory: 'dataset/coco/train2017/000000303703.jpg'

fail to map sample transform [Decode_eb3ead] with error: [Errno 2] No such file or directory: 'dataset/coco/train2017/000000027513.jpg' and stack:
Traceback (most recent call last):
  File "/workspace/zhaokang/SSOD/PaddleDetection/ppdet/data/reader.py", line 461, in __iter__
    unlabel_samples = next(self.unlabel_loader_iter)
  File "/usr/local/python3.7.0/lib/python3.7/site-packages/paddle/fluid/dataloader/dataloader_iter.py", line 773, in __next__
    six.reraise(*sys.exc_info())
  File "/usr/local/python3.7.0/lib/python3.7/site-packages/six.py", line 719, in reraise
    raise value
  File "/usr/local/python3.7.0/lib/python3.7/site-packages/paddle/fluid/dataloader/dataloader_iter.py", line 746, in __next__
    data = self._reader.read_next_var_list()
StopIteration

During handling of the above exception, another exception occurred:

Traceback (most recent call last):
  File "/workspace/zhaokang/SSOD/PaddleDetection/ppdet/data/reader.py", line 347, in __call__
    data = f(data)
  File "/workspace/zhaokang/SSOD/PaddleDetection/ppdet/data/transform/operators.py", line 105, in __call__
    sample = self.apply(sample, context)
  File "/workspace/zhaokang/SSOD/PaddleDetection/ppdet/data/transform/operators.py", line 122, in apply
    with open(sample['im_file'], 'rb') as f:
FileNotFoundError: [Errno 2] No such file or directory: 'dataset/coco/train2017/000000027513.jpg'

Exception in thread Thread-331:
Traceback (most recent call last):
  File "/usr/local/python3.7.0/lib/python3.7/threading.py", line 917, in _bootstrap_inner
    self.run()
  File "/usr/local/python3.7.0/lib/python3.7/threading.py", line 865, in run
    self._target(*self._args, **self._kwargs)
  File "/usr/local/python3.7.0/lib/python3.7/site-packages/paddle/fluid/dataloader/dataloader_iter.py", line 534, in _thread_loop
    batch = self._get_data()
  File "/usr/local/python3.7.0/lib/python3.7/site-packages/paddle/fluid/dataloader/dataloader_iter.py", line 671, in _get_data
    batch.reraise()
  File "/usr/local/python3.7.0/lib/python3.7/site-packages/paddle/fluid/dataloader/worker.py", line 169, in reraise
    raise self.exc_type(msg)
FileNotFoundError: DataLoader worker(1) caught FileNotFoundError with message:
Traceback (most recent call last):
  File "/workspace/zhaokang/SSOD/PaddleDetection/ppdet/data/reader.py", line 461, in __iter__
    unlabel_samples = next(self.unlabel_loader_iter)
  File "/usr/local/python3.7.0/lib/python3.7/site-packages/paddle/fluid/dataloader/dataloader_iter.py", line 773, in __next__
    six.reraise(*sys.exc_info())
  File "/usr/local/python3.7.0/lib/python3.7/site-packages/six.py", line 719, in reraise
    raise value
  File "/usr/local/python3.7.0/lib/python3.7/site-packages/paddle/fluid/dataloader/dataloader_iter.py", line 746, in __next__
    data = self._reader.read_next_var_list()
StopIteration

During handling of the above exception, another exception occurred:

Traceback (most recent call last):
  File "/usr/local/python3.7.0/lib/python3.7/site-packages/paddle/fluid/dataloader/worker.py", line 336, in _worker_loop
    batch = fetcher.fetch(indices)
  File "/usr/local/python3.7.0/lib/python3.7/site-packages/paddle/fluid/dataloader/fetcher.py", line 121, in fetch
    data.append(self.dataset[idx])
  File "/workspace/zhaokang/SSOD/PaddleDetection/ppdet/data/source/coco.py", line 587, in __getitem__
    return self.transform(roidb)
  File "/workspace/zhaokang/SSOD/PaddleDetection/ppdet/data/reader.py", line 353, in __call__
    raise e
  File "/workspace/zhaokang/SSOD/PaddleDetection/ppdet/data/reader.py", line 347, in __call__
    data = f(data)
  File "/workspace/zhaokang/SSOD/PaddleDetection/ppdet/data/transform/operators.py", line 105, in __call__
    sample = self.apply(sample, context)
  File "/workspace/zhaokang/SSOD/PaddleDetection/ppdet/data/transform/operators.py", line 122, in apply
    with open(sample['im_file'], 'rb') as f:
FileNotFoundError: [Errno 2] No such file or directory: 'dataset/coco/train2017/000000027513.jpg'


Exception in thread Thread-330:
Traceback (most recent call last):
  File "/usr/local/python3.7.0/lib/python3.7/threading.py", line 917, in _bootstrap_inner
    self.run()
  File "/usr/local/python3.7.0/lib/python3.7/threading.py", line 865, in run
    self._target(*self._args, **self._kwargs)
  File "/usr/local/python3.7.0/lib/python3.7/site-packages/paddle/fluid/dataloader/dataloader_iter.py", line 534, in _thread_loop
    batch = self._get_data()
  File "/usr/local/python3.7.0/lib/python3.7/site-packages/paddle/fluid/dataloader/dataloader_iter.py", line 671, in _get_data
    batch.reraise()
  File "/usr/local/python3.7.0/lib/python3.7/site-packages/paddle/fluid/dataloader/worker.py", line 169, in reraise
    raise self.exc_type(msg)
FileNotFoundError: DataLoader worker(1) caught FileNotFoundError with message:
Traceback (most recent call last):
  File "/workspace/zhaokang/SSOD/PaddleDetection/ppdet/data/reader.py", line 455, in __iter__
    label_samples = next(self.label_loader_iter)
  File "/usr/local/python3.7.0/lib/python3.7/site-packages/paddle/fluid/dataloader/dataloader_iter.py", line 773, in __next__
    six.reraise(*sys.exc_info())
  File "/usr/local/python3.7.0/lib/python3.7/site-packages/six.py", line 719, in reraise
    raise value
  File "/usr/local/python3.7.0/lib/python3.7/site-packages/paddle/fluid/dataloader/dataloader_iter.py", line 746, in __next__
    data = self._reader.read_next_var_list()
StopIteration

During handling of the above exception, another exception occurred:

Traceback (most recent call last):
  File "/usr/local/python3.7.0/lib/python3.7/site-packages/paddle/fluid/dataloader/worker.py", line 336, in _worker_loop
    batch = fetcher.fetch(indices)
  File "/usr/local/python3.7.0/lib/python3.7/site-packages/paddle/fluid/dataloader/fetcher.py", line 121, in fetch
    data.append(self.dataset[idx])
  File "/workspace/zhaokang/SSOD/PaddleDetection/ppdet/data/source/coco.py", line 587, in __getitem__
    return self.transform(roidb)
  File "/workspace/zhaokang/SSOD/PaddleDetection/ppdet/data/reader.py", line 353, in __call__
    raise e
  File "/workspace/zhaokang/SSOD/PaddleDetection/ppdet/data/reader.py", line 347, in __call__
    data = f(data)
  File "/workspace/zhaokang/SSOD/PaddleDetection/ppdet/data/transform/operators.py", line 105, in __call__
    sample = self.apply(sample, context)
  File "/workspace/zhaokang/SSOD/PaddleDetection/ppdet/data/transform/operators.py", line 122, in apply
    with open(sample['im_file'], 'rb') as f:
FileNotFoundError: [Errno 2] No such file or directory: 'dataset/coco/train2017/000000303703.jpg'


fail to map sample transform [Decode_788c3c] with error: [Errno 2] No such file or directory: 'dataset/coco/train2017/000000249825.jpg' and stack:
Traceback (most recent call last):
  File "/workspace/zhaokang/SSOD/PaddleDetection/ppdet/data/reader.py", line 455, in __iter__
    label_samples = next(self.label_loader_iter)
  File "/usr/local/python3.7.0/lib/python3.7/site-packages/paddle/fluid/dataloader/dataloader_iter.py", line 773, in __next__
    six.reraise(*sys.exc_info())
  File "/usr/local/python3.7.0/lib/python3.7/site-packages/six.py", line 719, in reraise
    raise value
  File "/usr/local/python3.7.0/lib/python3.7/site-packages/paddle/fluid/dataloader/dataloader_iter.py", line 746, in __next__
    data = self._reader.read_next_var_list()
StopIteration

During handling of the above exception, another exception occurred:

Traceback (most recent call last):
  File "/workspace/zhaokang/SSOD/PaddleDetection/ppdet/data/reader.py", line 347, in __call__
    data = f(data)
  File "/workspace/zhaokang/SSOD/PaddleDetection/ppdet/data/transform/operators.py", line 105, in __call__
    sample = self.apply(sample, context)
  File "/workspace/zhaokang/SSOD/PaddleDetection/ppdet/data/transform/operators.py", line 122, in apply
    with open(sample['im_file'], 'rb') as f:
FileNotFoundError: [Errno 2] No such file or directory: 'dataset/coco/train2017/000000249825.jpg'

fail to map sample transform [Decode_eb3ead] with error: [Errno 2] No such file or directory: 'dataset/coco/train2017/000000443465.jpg' and stack:
Traceback (most recent call last):
  File "/workspace/zhaokang/SSOD/PaddleDetection/ppdet/data/reader.py", line 461, in __iter__
    unlabel_samples = next(self.unlabel_loader_iter)
  File "/usr/local/python3.7.0/lib/python3.7/site-packages/paddle/fluid/dataloader/dataloader_iter.py", line 773, in __next__
    six.reraise(*sys.exc_info())
  File "/usr/local/python3.7.0/lib/python3.7/site-packages/six.py", line 719, in reraise
    raise value
  File "/usr/local/python3.7.0/lib/python3.7/site-packages/paddle/fluid/dataloader/dataloader_iter.py", line 746, in __next__
    data = self._reader.read_next_var_list()
StopIteration

During handling of the above exception, another exception occurred:

Traceback (most recent call last):
  File "/workspace/zhaokang/SSOD/PaddleDetection/ppdet/data/reader.py", line 347, in __call__
    data = f(data)
  File "/workspace/zhaokang/SSOD/PaddleDetection/ppdet/data/transform/operators.py", line 105, in __call__
    sample = self.apply(sample, context)
  File "/workspace/zhaokang/SSOD/PaddleDetection/ppdet/data/transform/operators.py", line 122, in apply
    with open(sample['im_file'], 'rb') as f:
FileNotFoundError: [Errno 2] No such file or directory: 'dataset/coco/train2017/000000443465.jpg'

fail to map sample transform [Decode_788c3c] with error: [Errno 2] No such file or directory: 'dataset/coco/train2017/000000040746.jpg' and stack:
Traceback (most recent call last):
  File "/workspace/zhaokang/SSOD/PaddleDetection/ppdet/data/reader.py", line 455, in __iter__
    unlabel_samples = next(self.unlabel_loader_iter)
  File "/usr/local/python3.7.0/lib/python3.7/site-packages/paddle/fluid/dataloader/dataloader_iter.py", line 773, in __next__
    six.reraise(*sys.exc_info())
  File "/usr/local/python3.7.0/lib/python3.7/site-packages/six.py", line 719, in reraise
    raise value
  File "/usr/local/python3.7.0/lib/python3.7/site-packages/paddle/fluid/dataloader/dataloader_iter.py", line 746, in __next__
    data = self._reader.read_next_var_list()
StopIteration

During handling of the above exception, another exception occurred:

Traceback (most recent call last):
  File "/workspace/zhaokang/SSOD/PaddleDetection/ppdet/data/reader.py", line 347, in __call__
    except Exception as e:
  File "/workspace/zhaokang/SSOD/PaddleDetection/ppdet/data/transform/operators.py", line 105, in __call__
    sample = self.apply(sample, context)
  File "/workspace/zhaokang/SSOD/PaddleDetection/ppdet/data/transform/operators.py", line 122, in apply
    with open(sample['im_file'], 'rb') as f:
FileNotFoundError: [Errno 2] No such file or directory: 'dataset/coco/train2017/000000040746.jpg'

fail to map sample transform [Decode_eb3ead] with error: [Errno 2] No such file or directory: 'dataset/coco/train2017/000000068352.jpg' and stack:
Traceback (most recent call last):
  File "/workspace/zhaokang/SSOD/PaddleDetection/ppdet/data/reader.py", line 461, in __iter__
    label_samples[0],  # sup weak
  File "/usr/local/python3.7.0/lib/python3.7/site-packages/paddle/fluid/dataloader/dataloader_iter.py", line 773, in __next__
    six.reraise(*sys.exc_info())
  File "/usr/local/python3.7.0/lib/python3.7/site-packages/six.py", line 719, in reraise
    raise value
  File "/usr/local/python3.7.0/lib/python3.7/site-packages/paddle/fluid/dataloader/dataloader_iter.py", line 746, in __next__
    data = self._reader.read_next_var_list()
StopIteration

During handling of the above exception, another exception occurred:

Traceback (most recent call last):
  File "/workspace/zhaokang/SSOD/PaddleDetection/ppdet/data/reader.py", line 347, in __call__
    except Exception as e:
  File "/workspace/zhaokang/SSOD/PaddleDetection/ppdet/data/transform/operators.py", line 105, in __call__
    sample = self.apply(sample, context)
  File "/workspace/zhaokang/SSOD/PaddleDetection/ppdet/data/transform/operators.py", line 122, in apply
    with open(sample['im_file'], 'rb') as f:
FileNotFoundError: [Errno 2] No such file or directory: 'dataset/coco/train2017/000000068352.jpg'

fail to map sample transform [Decode_788c3c] with error: [Errno 2] No such file or directory: 'dataset/coco/train2017/000000002239.jpg' and stack:
Traceback (most recent call last):
  File "/workspace/zhaokang/SSOD/PaddleDetection/ppdet/data/reader.py", line 455, in __iter__
    unlabel_samples = next(self.unlabel_loader_iter)
  File "/usr/local/python3.7.0/lib/python3.7/site-packages/paddle/fluid/dataloader/dataloader_iter.py", line 746, in __next__
    data = self._reader.read_next_var_list()
SystemError: (Fatal) Blocking queue is killed because the data reader raises an exception.
  [Hint: Expected killed_ != true, but received killed_:1 == true:1.] (at /paddle/paddle/fluid/operators/reader/blocking_queue.h:166)


During handling of the above exception, another exception occurred:

Traceback (most recent call last):
  File "/workspace/zhaokang/SSOD/PaddleDetection/ppdet/data/reader.py", line 347, in __call__
    except Exception as e:
  File "/workspace/zhaokang/SSOD/PaddleDetection/ppdet/data/transform/operators.py", line 105, in __call__
    sample = self.apply(sample, context)
  File "/workspace/zhaokang/SSOD/PaddleDetection/ppdet/data/transform/operators.py", line 122, in apply
    with open(sample['im_file'], 'rb') as f:
FileNotFoundError: [Errno 2] No such file or directory: 'dataset/coco/train2017/000000002239.jpg'

fail to map sample transform [Decode_788c3c] with error: [Errno 2] No such file or directory: 'dataset/coco/train2017/000000429283.jpg' and stack:
Traceback (most recent call last):
  File "/workspace/zhaokang/SSOD/PaddleDetection/ppdet/data/reader.py", line 455, in __iter__
    unlabel_samples = next(self.unlabel_loader_iter)
  File "/usr/local/python3.7.0/lib/python3.7/site-packages/paddle/fluid/dataloader/dataloader_iter.py", line 746, in __next__
    data = self._reader.read_next_var_list()
SystemError: (Fatal) Blocking queue is killed because the data reader raises an exception.
  [Hint: Expected killed_ != true, but received killed_:1 == true:1.] (at /paddle/paddle/fluid/operators/reader/blocking_queue.h:166)


During handling of the above exception, another exception occurred:

Traceback (most recent call last):
  File "/workspace/zhaokang/SSOD/PaddleDetection/ppdet/data/reader.py", line 347, in __call__
    except Exception as e:
  File "/workspace/zhaokang/SSOD/PaddleDetection/ppdet/data/transform/operators.py", line 105, in __call__
    sample = self.apply(sample, context)
  File "/workspace/zhaokang/SSOD/PaddleDetection/ppdet/data/transform/operators.py", line 122, in apply
    with open(sample['im_file'], 'rb') as f:
FileNotFoundError: [Errno 2] No such file or directory: 'dataset/coco/train2017/000000429283.jpg'

fail to map sample transform [Decode_788c3c] with error: [Errno 2] No such file or directory: 'dataset/coco/train2017/000000367106.jpg' and stack:
Traceback (most recent call last):
  File "/workspace/zhaokang/SSOD/PaddleDetection/ppdet/data/reader.py", line 455, in __iter__
    unlabel_samples = next(self.unlabel_loader_iter)
  File "/usr/local/python3.7.0/lib/python3.7/site-packages/paddle/fluid/dataloader/dataloader_iter.py", line 746, in __next__
    data = self._reader.read_next_var_list()
SystemError: (Fatal) Blocking queue is killed because the data reader raises an exception.
  [Hint: Expected killed_ != true, but received killed_:1 == true:1.] (at /paddle/paddle/fluid/operators/reader/blocking_queue.h:166)


During handling of the above exception, another exception occurred:

Traceback (most recent call last):
  File "/workspace/zhaokang/SSOD/PaddleDetection/ppdet/data/reader.py", line 347, in __call__
    except Exception as e:
  File "/workspace/zhaokang/SSOD/PaddleDetection/ppdet/data/transform/operators.py", line 105, in __call__
    sample = self.apply(sample, context)
  File "/workspace/zhaokang/SSOD/PaddleDetection/ppdet/data/transform/operators.py", line 122, in apply
    with open(sample['im_file'], 'rb') as f:
FileNotFoundError: [Errno 2] No such file or directory: 'dataset/coco/train2017/000000367106.jpg'

fail to map sample transform [Decode_788c3c] with error: [Errno 2] No such file or directory: 'dataset/coco/train2017/000000161222.jpg' and stack:
Traceback (most recent call last):
  File "/workspace/zhaokang/SSOD/PaddleDetection/ppdet/data/reader.py", line 455, in __iter__
    unlabel_samples = next(self.unlabel_loader_iter)
  File "/usr/local/python3.7.0/lib/python3.7/site-packages/paddle/fluid/dataloader/dataloader_iter.py", line 746, in __next__
    data = self._reader.read_next_var_list()
SystemError: (Fatal) Blocking queue is killed because the data reader raises an exception.
  [Hint: Expected killed_ != true, but received killed_:1 == true:1.] (at /paddle/paddle/fluid/operators/reader/blocking_queue.h:166)


During handling of the above exception, another exception occurred:

Traceback (most recent call last):
  File "/workspace/zhaokang/SSOD/PaddleDetection/ppdet/data/reader.py", line 347, in __call__
    except Exception as e:
  File "/workspace/zhaokang/SSOD/PaddleDetection/ppdet/data/transform/operators.py", line 105, in __call__
    sample = self.apply(sample, context)
  File "/workspace/zhaokang/SSOD/PaddleDetection/ppdet/data/transform/operators.py", line 122, in apply
    with open(sample['im_file'], 'rb') as f:
FileNotFoundError: [Errno 2] No such file or directory: 'dataset/coco/train2017/000000161222.jpg'

fail to map sample transform [Decode_788c3c] with error: [Errno 2] No such file or directory: 'dataset/coco/train2017/000000321403.jpg' and stack:
Traceback (most recent call last):
  File "/workspace/zhaokang/SSOD/PaddleDetection/ppdet/data/reader.py", line 455, in __iter__
    unlabel_samples = next(self.unlabel_loader_iter)
  File "/usr/local/python3.7.0/lib/python3.7/site-packages/paddle/fluid/dataloader/dataloader_iter.py", line 746, in __next__
    data = self._reader.read_next_var_list()
SystemError: (Fatal) Blocking queue is killed because the data reader raises an exception.
  [Hint: Expected killed_ != true, but received killed_:1 == true:1.] (at /paddle/paddle/fluid/operators/reader/blocking_queue.h:166)


During handling of the above exception, another exception occurred:

Traceback (most recent call last):
  File "/workspace/zhaokang/SSOD/PaddleDetection/ppdet/data/reader.py", line 347, in __call__
    except Exception as e:
  File "/workspace/zhaokang/SSOD/PaddleDetection/ppdet/data/transform/operators.py", line 105, in __call__
    sample = self.apply(sample, context)
  File "/workspace/zhaokang/SSOD/PaddleDetection/ppdet/data/transform/operators.py", line 122, in apply
    with open(sample['im_file'], 'rb') as f:
FileNotFoundError: [Errno 2] No such file or directory: 'dataset/coco/train2017/000000321403.jpg'

fail to map sample transform [Decode_788c3c] with error: [Errno 2] No such file or directory: 'dataset/coco/train2017/000000459763.jpg' and stack:
Traceback (most recent call last):
  File "/workspace/zhaokang/SSOD/PaddleDetection/ppdet/data/reader.py", line 455, in __iter__
    unlabel_samples = next(self.unlabel_loader_iter)
  File "/usr/local/python3.7.0/lib/python3.7/site-packages/paddle/fluid/dataloader/dataloader_iter.py", line 746, in __next__
    data = self._reader.read_next_var_list()
SystemError: (Fatal) Blocking queue is killed because the data reader raises an exception.
  [Hint: Expected killed_ != true, but received killed_:1 == true:1.] (at /paddle/paddle/fluid/operators/reader/blocking_queue.h:166)


During handling of the above exception, another exception occurred:

Traceback (most recent call last):
  File "/workspace/zhaokang/SSOD/PaddleDetection/ppdet/data/reader.py", line 347, in __call__
    except Exception as e:
  File "/workspace/zhaokang/SSOD/PaddleDetection/ppdet/data/transform/operators.py", line 105, in __call__
    sample = self.apply(sample, context)
  File "/workspace/zhaokang/SSOD/PaddleDetection/ppdet/data/transform/operators.py", line 122, in apply
    with open(sample['im_file'], 'rb') as f:
FileNotFoundError: [Errno 2] No such file or directory: 'dataset/coco/train2017/000000459763.jpg'

fail to map sample transform [Decode_788c3c] with error: [Errno 2] No such file or directory: 'dataset/coco/train2017/000000330726.jpg' and stack:
Traceback (most recent call last):
  File "/workspace/zhaokang/SSOD/PaddleDetection/ppdet/data/reader.py", line 455, in __iter__
    unlabel_samples = next(self.unlabel_loader_iter)
  File "/usr/local/python3.7.0/lib/python3.7/site-packages/paddle/fluid/dataloader/dataloader_iter.py", line 746, in __next__
    data = self._reader.read_next_var_list()
SystemError: (Fatal) Blocking queue is killed because the data reader raises an exception.
  [Hint: Expected killed_ != true, but received killed_:1 == true:1.] (at /paddle/paddle/fluid/operators/reader/blocking_queue.h:166)


During handling of the above exception, another exception occurred:

Traceback (most recent call last):
  File "/workspace/zhaokang/SSOD/PaddleDetection/ppdet/data/reader.py", line 347, in __call__
    except Exception as e:
  File "/workspace/zhaokang/SSOD/PaddleDetection/ppdet/data/transform/operators.py", line 105, in __call__
    sample = self.apply(sample, context)
  File "/workspace/zhaokang/SSOD/PaddleDetection/ppdet/data/transform/operators.py", line 122, in apply
    with open(sample['im_file'], 'rb') as f:
FileNotFoundError: [Errno 2] No such file or directory: 'dataset/coco/train2017/000000330726.jpg'

fail to map sample transform [Decode_788c3c] with error: [Errno 2] No such file or directory: 'dataset/coco/train2017/000000458103.jpg' and stack:
Traceback (most recent call last):
  File "/workspace/zhaokang/SSOD/PaddleDetection/ppdet/data/reader.py", line 455, in __iter__
    unlabel_samples = next(self.unlabel_loader_iter)
  File "/usr/local/python3.7.0/lib/python3.7/site-packages/paddle/fluid/dataloader/dataloader_iter.py", line 746, in __next__
    data = self._reader.read_next_var_list()
SystemError: (Fatal) Blocking queue is killed because the data reader raises an exception.
  [Hint: Expected killed_ != true, but received killed_:1 == true:1.] (at /paddle/paddle/fluid/operators/reader/blocking_queue.h:166)


During handling of the above exception, another exception occurred:

Traceback (most recent call last):
  File "/workspace/zhaokang/SSOD/PaddleDetection/ppdet/data/reader.py", line 347, in __call__
    except Exception as e:
  File "/workspace/zhaokang/SSOD/PaddleDetection/ppdet/data/transform/operators.py", line 105, in __call__
    sample = self.apply(sample, context)
  File "/workspace/zhaokang/SSOD/PaddleDetection/ppdet/data/transform/operators.py", line 122, in apply
    with open(sample['im_file'], 'rb') as f:
FileNotFoundError: [Errno 2] No such file or directory: 'dataset/coco/train2017/000000458103.jpg'

Exception in thread Thread-332:
Traceback (most recent call last):
  File "/usr/local/python3.7.0/lib/python3.7/threading.py", line 917, in _bootstrap_inner
    self.run()
  File "/usr/local/python3.7.0/lib/python3.7/threading.py", line 865, in run
    self._target(*self._args, **self._kwargs)
  File "/usr/local/python3.7.0/lib/python3.7/site-packages/paddle/fluid/dataloader/dataloader_iter.py", line 534, in _thread_loop
    batch = self._get_data()
  File "/usr/local/python3.7.0/lib/python3.7/site-packages/paddle/fluid/dataloader/dataloader_iter.py", line 671, in _get_data
    batch.reraise()
  File "/usr/local/python3.7.0/lib/python3.7/site-packages/paddle/fluid/dataloader/worker.py", line 169, in reraise
    raise self.exc_type(msg)
FileNotFoundError: DataLoader worker(0) caught FileNotFoundError with message:
Traceback (most recent call last):
  File "/workspace/zhaokang/SSOD/PaddleDetection/ppdet/data/reader.py", line 455, in __iter__
    unlabel_samples = next(self.unlabel_loader_iter)
  File "/usr/local/python3.7.0/lib/python3.7/site-packages/paddle/fluid/dataloader/dataloader_iter.py", line 746, in __next__
    data = self._reader.read_next_var_list()
SystemError: (Fatal) Blocking queue is killed because the data reader raises an exception.
  [Hint: Expected killed_ != true, but received killed_:1 == true:1.] (at /paddle/paddle/fluid/operators/reader/blocking_queue.h:166)


During handling of the above exception, another exception occurred:

Traceback (most recent call last):
  File "/usr/local/python3.7.0/lib/python3.7/site-packages/paddle/fluid/dataloader/worker.py", line 336, in _worker_loop
    batch = fetcher.fetch(indices)
  File "/usr/local/python3.7.0/lib/python3.7/site-packages/paddle/fluid/dataloader/fetcher.py", line 121, in fetch
    data.append(self.dataset[idx])
  File "/workspace/zhaokang/SSOD/PaddleDetection/ppdet/data/source/coco.py", line 587, in __getitem__
    return self.transform(roidb)
  File "/workspace/zhaokang/SSOD/PaddleDetection/ppdet/data/reader.py", line 353, in __call__
  File "/workspace/zhaokang/SSOD/PaddleDetection/ppdet/data/reader.py", line 347, in __call__
    except Exception as e:
  File "/workspace/zhaokang/SSOD/PaddleDetection/ppdet/data/transform/operators.py", line 105, in __call__
    sample = self.apply(sample, context)
  File "/workspace/zhaokang/SSOD/PaddleDetection/ppdet/data/transform/operators.py", line 122, in apply
    with open(sample['im_file'], 'rb') as f:
FileNotFoundError: [Errno 2] No such file or directory: 'dataset/coco/train2017/000000002239.jpg'


Traceback (most recent call last):
  File "/workspace/zhaokang/SSOD/PaddleDetection/ppdet/data/reader.py", line 455, in __iter__
    unlabel_samples = next(self.unlabel_loader_iter)
  File "/usr/local/python3.7.0/lib/python3.7/site-packages/paddle/fluid/dataloader/dataloader_iter.py", line 746, in __next__
    data = self._reader.read_next_var_list()
SystemError: (Fatal) Blocking queue is killed because the data reader raises an exception.
  [Hint: Expected killed_ != true, but received killed_:1 == true:1.] (at /paddle/paddle/fluid/operators/reader/blocking_queue.h:166)


During handling of the above exception, another exception occurred:

Traceback (most recent call last):
  File "tools/train.py", line 205, in <module>
  File "tools/train.py", line 201, in main
    if __name__ == "__main__":
  File "tools/train.py", line 154, in run
    def main():
  File "/workspace/zhaokang/SSOD/PaddleDetection/ppdet/engine/trainer_ssod.py", line 247, in train
    
  File "/workspace/zhaokang/SSOD/PaddleDetection/ppdet/data/reader.py", line 590, in __next__
    
  File "/workspace/zhaokang/SSOD/PaddleDetection/ppdet/data/reader.py", line 458, in __iter__
    unlabel_samples = next(self.unlabel_loader_iter)
  File "/usr/local/python3.7.0/lib/python3.7/site-packages/paddle/fluid/dataloader/dataloader_iter.py", line 746, in __next__
    data = self._reader.read_next_var_list()
SystemError: (Fatal) Blocking queue is killed because the data reader raises an exception.
  [Hint: Expected killed_ != true, but received killed_:1 == true:1.] (at /paddle/paddle/fluid/operators/reader/blocking_queue.h:166)

grep: warning: GREP_OPTIONS is deprecated; please use an alias or script
Warning: Unable to use numba in PP-Tracking, please install numba, for example(python3.7): `pip install numba==0.56.4`
Warning: Unable to use numba in PP-Tracking, please install numba, for example(python3.7): `pip install numba==0.56.4`
Warning: import ppdet from source directory without installing, run 'python setup.py install' to install ppdet firstly
I0319 13:08:36.690529  7473 gen_comm_id_helper.cc:205] Server listening on: 127.0.0.1:35322 successful.
I0319 13:08:39.692555  7473 nccl_context.cc:83] init nccl context nranks: 8 local rank: 7 gpu id: 7 ring id: 0
W0319 13:08:41.252352  7473 gpu_resources.cc:61] Please NOTE: device: 7, GPU Compute Capability: 6.1, Driver API Version: 10.2, Runtime API Version: 10.2
W0319 13:08:41.257472  7473 gpu_resources.cc:91] device: 7, cuDNN Version: 7.6.
Config dataset_dir dataset/coco is not exits, dataset config is not valid
Dataset /workspace/dataset/coco is not valid for reason above, try searching /root/.cache/paddle/dataset or downloading dataset...


--------------------------------------
C++ Traceback (most recent call last):
--------------------------------------
No stack trace in paddle, may be caused by external reasons.

----------------------
Error Message Summary:
----------------------
FatalError: `Termination signal` is detected by the operating system.
  [TimeInfo: *** Aborted at 1679231441 (unix time) try "date -d @1679231441" if you are using GNU date ***]
  [SignalInfo: *** SIGTERM (@0x1cd8) received by PID 7473 (TID 0x7f1f43f90700) from PID 7384 ***]

grep: warning: GREP_OPTIONS is deprecated; please use an alias or script
grep: warning: GREP_OPTIONS is deprecated; please use an alias or script
Warning: Unable to use numba in PP-Tracking, please install numba, for example(python3.7): `pip install numba==0.56.4`
Warning: Unable to use numba in PP-Tracking, please install numba, for example(python3.7): `pip install numba==0.56.4`
Warning: import ppdet from source directory without installing, run 'python setup.py install' to install ppdet firstly
I0319 13:12:46.337882  8424 gen_comm_id_helper.cc:205] Server listening on: 127.0.0.1:58581 successful.
I0319 13:12:49.300420  8424 nccl_context.cc:83] init nccl context nranks: 8 local rank: 7 gpu id: 7 ring id: 0
W0319 13:12:50.845530  8424 gpu_resources.cc:61] Please NOTE: device: 7, GPU Compute Capability: 6.1, Driver API Version: 10.2, Runtime API Version: 10.2
W0319 13:12:50.850561  8424 gpu_resources.cc:91] device: 7, cuDNN Version: 7.6.
loading annotations into memory...
Done (t=2.00s)
creating index...
index created!
loading annotations into memory...
Done (t=0.55s)
creating index...
index created!
Annotation file: dataset/coco/semi_annotations/instances_train2017.1@10-unlabeled.json does not contains ground truth and load image information only.
W0319 13:13:12.019234  8424 reducer.cc:694] All parameters are involved in the backward pass. It is recommended to set find_unused_parameters to False to improve performance. However, if unused parameters appear in subsequent iterative training, then an error will occur. Please make it clear that in the subsequent training, there will be no parameters that are not used in the backward pass, and then set find_unused_parameters


--------------------------------------
C++ Traceback (most recent call last):
--------------------------------------
No stack trace in paddle, may be caused by external reasons.

----------------------
Error Message Summary:
----------------------
FatalError: `Termination signal` is detected by the operating system.
  [TimeInfo: *** Aborted at 1679231639 (unix time) try "date -d @1679231639" if you are using GNU date ***]
  [SignalInfo: *** SIGTERM (@0x208f) received by PID 8424 (TID 0x7fb76546d700) from PID 8335 ***]

